[2025-01-30T08:49:39.777+0000] {local_task_job_runner.py:123} INFO - ::group::Pre task execution logs
[2025-01-30T08:49:39.800+0000] {taskinstance.py:2613} INFO - Dependencies all met for dep_context=non-requeueable deps ti=<TaskInstance: hello_airflow.etl_task manual__2025-01-23T12:14:19.972456+00:00 [queued]>
[2025-01-30T08:49:39.810+0000] {taskinstance.py:2613} INFO - Dependencies all met for dep_context=requeueable deps ti=<TaskInstance: hello_airflow.etl_task manual__2025-01-23T12:14:19.972456+00:00 [queued]>
[2025-01-30T08:49:39.810+0000] {taskinstance.py:2866} INFO - Starting attempt 29 of 29
[2025-01-30T08:49:39.822+0000] {taskinstance.py:2889} INFO - Executing <Task(BashOperator): etl_task> on 2025-01-23 12:14:19.972456+00:00
[2025-01-30T08:49:39.834+0000] {standard_task_runner.py:104} INFO - Running: ['***', 'tasks', 'run', 'hello_***', 'etl_task', 'manual__2025-01-23T12:14:19.972456+00:00', '--job-id', '101', '--raw', '--subdir', 'DAGS_FOLDER/pipeline.py', '--cfg-path', '/tmp/tmp4r8hy7fy']
[2025-01-30T08:49:39.838+0000] {standard_task_runner.py:105} INFO - Job 101: Subtask etl_task
[2025-01-30T08:49:39.841+0000] {logging_mixin.py:190} WARNING - /home/***/.local/lib/python3.12/site-packages/***/task/task_runner/standard_task_runner.py:70 DeprecationWarning: This process (pid=206) is multi-threaded, use of fork() may lead to deadlocks in the child.
[2025-01-30T08:49:39.844+0000] {standard_task_runner.py:72} INFO - Started process 207 to run task
[2025-01-30T08:49:39.906+0000] {task_command.py:467} INFO - Running <TaskInstance: hello_airflow.etl_task manual__2025-01-23T12:14:19.972456+00:00 [running]> on host b82d3320e908
[2025-01-30T08:49:39.976+0000] {taskinstance.py:3132} INFO - Exporting env vars: AIRFLOW_CTX_DAG_OWNER='***' AIRFLOW_CTX_DAG_ID='hello_***' AIRFLOW_CTX_TASK_ID='etl_task' AIRFLOW_CTX_EXECUTION_DATE='2025-01-23T12:14:19.972456+00:00' AIRFLOW_CTX_TRY_NUMBER='29' AIRFLOW_CTX_DAG_RUN_ID='manual__2025-01-23T12:14:19.972456+00:00'
[2025-01-30T08:49:39.977+0000] {taskinstance.py:731} INFO - ::endgroup::
[2025-01-30T08:49:39.995+0000] {subprocess.py:78} INFO - Tmp dir root location: /tmp
[2025-01-30T08:49:39.995+0000] {subprocess.py:88} INFO - Running command: ['/usr/bin/bash', '-c', 'python /opt/***/dags/etl.py']
[2025-01-30T08:49:40.001+0000] {subprocess.py:99} INFO - Output:
[2025-01-30T08:49:40.838+0000] {subprocess.py:106} INFO - /opt/spark/bin/load-spark-env.sh: line 68: ps: command not found
[2025-01-30T08:49:42.172+0000] {subprocess.py:106} INFO - Setting default log level to "WARN".
[2025-01-30T08:49:42.172+0000] {subprocess.py:106} INFO - To adjust logging level use sc.setLogLevel(newLevel). For SparkR, use setLogLevel(newLevel).
[2025-01-30T08:49:42.393+0000] {subprocess.py:106} INFO - 25/01/30 08:49:42 WARN NativeCodeLoader: Unable to load native-hadoop library for your platform... using builtin-java classes where applicable
[2025-01-30T08:49:44.141+0000] {subprocess.py:106} INFO - Traceback (most recent call last):
[2025-01-30T08:49:44.142+0000] {subprocess.py:106} INFO -   File "/opt/***/dags/etl.py", line 11, in <module>
[2025-01-30T08:49:44.142+0000] {subprocess.py:106} INFO -     df = spark.read.option("header", "true").option("inferSchema", "true").csv(f"{filepath_data}/spotify-2023.csv")
[2025-01-30T08:49:44.142+0000] {subprocess.py:106} INFO -          ^^^^^^^^^^^^^^^^^^^^^^^^^^^^^^^^^^^^^^^^^^^^^^^^^^^^^^^^^^^^^^^^^^^^^^^^^^^^^^^^^^^^^^^^^^^^^^^^^^^^^^^^^^
[2025-01-30T08:49:44.142+0000] {subprocess.py:106} INFO -   File "/home/***/.local/lib/python3.12/site-packages/pyspark/sql/readwriter.py", line 740, in csv
[2025-01-30T08:49:44.142+0000] {subprocess.py:106} INFO -     return self._df(self._jreader.csv(self._spark._sc._jvm.PythonUtils.toSeq(path)))
[2025-01-30T08:49:44.142+0000] {subprocess.py:106} INFO -                     ^^^^^^^^^^^^^^^^^^^^^^^^^^^^^^^^^^^^^^^^^^^^^^^^^^^^^^^^^^^^^^^
[2025-01-30T08:49:44.142+0000] {subprocess.py:106} INFO -   File "/home/***/.local/lib/python3.12/site-packages/py4j/java_gateway.py", line 1322, in __call__
[2025-01-30T08:49:44.142+0000] {subprocess.py:106} INFO -     return_value = get_return_value(
[2025-01-30T08:49:44.142+0000] {subprocess.py:106} INFO -                    ^^^^^^^^^^^^^^^^^
[2025-01-30T08:49:44.143+0000] {subprocess.py:106} INFO -   File "/home/***/.local/lib/python3.12/site-packages/pyspark/errors/exceptions/captured.py", line 185, in deco
[2025-01-30T08:49:44.143+0000] {subprocess.py:106} INFO -     raise converted from None
[2025-01-30T08:49:44.147+0000] {subprocess.py:106} INFO - pyspark.errors.exceptions.captured.AnalysisException: [PATH_NOT_FOUND] Path does not exist: file:/tmp/***tmpfk86b7kn/opt/***/data/spotify-2023.csv.
[2025-01-30T08:49:44.602+0000] {subprocess.py:110} INFO - Command exited with return code 1
[2025-01-30T08:49:44.611+0000] {taskinstance.py:3311} ERROR - Task failed with exception
Traceback (most recent call last):
  File "/home/airflow/.local/lib/python3.12/site-packages/airflow/models/taskinstance.py", line 767, in _execute_task
    result = _execute_callable(context=context, **execute_callable_kwargs)
             ^^^^^^^^^^^^^^^^^^^^^^^^^^^^^^^^^^^^^^^^^^^^^^^^^^^^^^^^^^^^^
  File "/home/airflow/.local/lib/python3.12/site-packages/airflow/models/taskinstance.py", line 733, in _execute_callable
    return ExecutionCallableRunner(
           ^^^^^^^^^^^^^^^^^^^^^^^^
  File "/home/airflow/.local/lib/python3.12/site-packages/airflow/utils/operator_helpers.py", line 252, in run
    return self.func(*args, **kwargs)
           ^^^^^^^^^^^^^^^^^^^^^^^^^^
  File "/home/airflow/.local/lib/python3.12/site-packages/airflow/models/baseoperator.py", line 422, in wrapper
    return func(self, *args, **kwargs)
           ^^^^^^^^^^^^^^^^^^^^^^^^^^^
  File "/home/airflow/.local/lib/python3.12/site-packages/airflow/operators/bash.py", line 276, in execute
    raise AirflowException(
airflow.exceptions.AirflowException: Bash command failed. The command returned a non-zero exit code 1.
[2025-01-30T08:49:44.614+0000] {taskinstance.py:1225} INFO - Marking task as FAILED. dag_id=hello_***, task_id=etl_task, run_id=manual__2025-01-23T12:14:19.972456+00:00, execution_date=20250123T121419, start_date=20250130T084939, end_date=20250130T084944
[2025-01-30T08:49:44.625+0000] {taskinstance.py:340} INFO - ::group::Post task execution logs
[2025-01-30T08:49:44.625+0000] {standard_task_runner.py:124} ERROR - Failed to execute job 101 for task etl_task (Bash command failed. The command returned a non-zero exit code 1.; 207)
Traceback (most recent call last):
  File "/home/airflow/.local/lib/python3.12/site-packages/airflow/task/task_runner/standard_task_runner.py", line 117, in _start_by_fork
    ret = args.func(args, dag=self.dag)
          ^^^^^^^^^^^^^^^^^^^^^^^^^^^^^
  File "/home/airflow/.local/lib/python3.12/site-packages/airflow/cli/cli_config.py", line 49, in command
    return func(*args, **kwargs)
           ^^^^^^^^^^^^^^^^^^^^^
  File "/home/airflow/.local/lib/python3.12/site-packages/airflow/utils/cli.py", line 116, in wrapper
    return f(*args, **kwargs)
           ^^^^^^^^^^^^^^^^^^
  File "/home/airflow/.local/lib/python3.12/site-packages/airflow/cli/commands/task_command.py", line 483, in task_run
    task_return_code = _run_task_by_selected_method(args, _dag, ti)
                       ^^^^^^^^^^^^^^^^^^^^^^^^^^^^^^^^^^^^^^^^^^^^
  File "/home/airflow/.local/lib/python3.12/site-packages/airflow/cli/commands/task_command.py", line 256, in _run_task_by_selected_method
    return _run_raw_task(args, ti)
           ^^^^^^^^^^^^^^^^^^^^^^^
  File "/home/airflow/.local/lib/python3.12/site-packages/airflow/cli/commands/task_command.py", line 341, in _run_raw_task
    return ti._run_raw_task(
           ^^^^^^^^^^^^^^^^^
  File "/home/airflow/.local/lib/python3.12/site-packages/airflow/utils/session.py", line 97, in wrapper
    return func(*args, session=session, **kwargs)
           ^^^^^^^^^^^^^^^^^^^^^^^^^^^^^^^^^^^^^^
  File "/home/airflow/.local/lib/python3.12/site-packages/airflow/models/taskinstance.py", line 3005, in _run_raw_task
    return _run_raw_task(
           ^^^^^^^^^^^^^^
  File "/home/airflow/.local/lib/python3.12/site-packages/airflow/models/taskinstance.py", line 273, in _run_raw_task
    TaskInstance._execute_task_with_callbacks(
  File "/home/airflow/.local/lib/python3.12/site-packages/airflow/models/taskinstance.py", line 3159, in _execute_task_with_callbacks
    result = self._execute_task(context, task_orig)
             ^^^^^^^^^^^^^^^^^^^^^^^^^^^^^^^^^^^^^^
  File "/home/airflow/.local/lib/python3.12/site-packages/airflow/models/taskinstance.py", line 3183, in _execute_task
    return _execute_task(self, context, task_orig)
           ^^^^^^^^^^^^^^^^^^^^^^^^^^^^^^^^^^^^^^^
  File "/home/airflow/.local/lib/python3.12/site-packages/airflow/models/taskinstance.py", line 767, in _execute_task
    result = _execute_callable(context=context, **execute_callable_kwargs)
             ^^^^^^^^^^^^^^^^^^^^^^^^^^^^^^^^^^^^^^^^^^^^^^^^^^^^^^^^^^^^^
  File "/home/airflow/.local/lib/python3.12/site-packages/airflow/models/taskinstance.py", line 733, in _execute_callable
    return ExecutionCallableRunner(
           ^^^^^^^^^^^^^^^^^^^^^^^^
  File "/home/airflow/.local/lib/python3.12/site-packages/airflow/utils/operator_helpers.py", line 252, in run
    return self.func(*args, **kwargs)
           ^^^^^^^^^^^^^^^^^^^^^^^^^^
  File "/home/airflow/.local/lib/python3.12/site-packages/airflow/models/baseoperator.py", line 422, in wrapper
    return func(self, *args, **kwargs)
           ^^^^^^^^^^^^^^^^^^^^^^^^^^^
  File "/home/airflow/.local/lib/python3.12/site-packages/airflow/operators/bash.py", line 276, in execute
    raise AirflowException(
airflow.exceptions.AirflowException: Bash command failed. The command returned a non-zero exit code 1.
[2025-01-30T08:49:44.657+0000] {local_task_job_runner.py:266} INFO - Task exited with return code 1
[2025-01-30T08:49:44.678+0000] {taskinstance.py:3895} INFO - 0 downstream tasks scheduled from follow-on schedule check
[2025-01-30T08:49:44.682+0000] {local_task_job_runner.py:245} INFO - ::endgroup::
