[2025-01-23T12:29:39.479+0000] {taskinstance.py:1159} INFO - Dependencies all met for dep_context=non-requeueable deps ti=<TaskInstance: hello_airflow.etl_task manual__2025-01-23T12:14:19.972456+00:00 [queued]>
[2025-01-23T12:29:39.484+0000] {taskinstance.py:1159} INFO - Dependencies all met for dep_context=requeueable deps ti=<TaskInstance: hello_airflow.etl_task manual__2025-01-23T12:14:19.972456+00:00 [queued]>
[2025-01-23T12:29:39.484+0000] {taskinstance.py:1361} INFO - Starting attempt 5 of 6
[2025-01-23T12:29:39.493+0000] {taskinstance.py:1382} INFO - Executing <Task(BashOperator): etl_task> on 2025-01-23 12:14:19.972456+00:00
[2025-01-23T12:29:39.496+0000] {standard_task_runner.py:57} INFO - Started process 602 to run task
[2025-01-23T12:29:39.499+0000] {standard_task_runner.py:84} INFO - Running: ['***', 'tasks', 'run', 'hello_***', 'etl_task', 'manual__2025-01-23T12:14:19.972456+00:00', '--job-id', '11', '--raw', '--subdir', 'DAGS_FOLDER/test.py', '--cfg-path', '/tmp/tmp7y9mft4t']
[2025-01-23T12:29:39.500+0000] {standard_task_runner.py:85} INFO - Job 11: Subtask etl_task
[2025-01-23T12:29:39.532+0000] {task_command.py:415} INFO - Running <TaskInstance: hello_airflow.etl_task manual__2025-01-23T12:14:19.972456+00:00 [running]> on host e73af8e58a44
[2025-01-23T12:29:39.579+0000] {taskinstance.py:1660} INFO - Exporting env vars: AIRFLOW_CTX_DAG_OWNER='***' AIRFLOW_CTX_DAG_ID='hello_***' AIRFLOW_CTX_TASK_ID='etl_task' AIRFLOW_CTX_EXECUTION_DATE='2025-01-23T12:14:19.972456+00:00' AIRFLOW_CTX_TRY_NUMBER='5' AIRFLOW_CTX_DAG_RUN_ID='manual__2025-01-23T12:14:19.972456+00:00'
[2025-01-23T12:29:39.580+0000] {subprocess.py:63} INFO - Tmp dir root location: /tmp
[2025-01-23T12:29:39.580+0000] {subprocess.py:75} INFO - Running command: ['/bin/bash', '-c', 'python /workspaces/spotify_popularity_predicition/etl.py']
[2025-01-23T12:29:39.585+0000] {subprocess.py:86} INFO - Output:
[2025-01-23T12:29:39.642+0000] {subprocess.py:93} INFO - python: can't open file '/workspaces/spotify_popularity_predicition/etl.py': [Errno 2] No such file or directory
[2025-01-23T12:29:39.644+0000] {subprocess.py:97} INFO - Command exited with return code 2
[2025-01-23T12:29:39.651+0000] {taskinstance.py:1943} ERROR - Task failed with exception
Traceback (most recent call last):
  File "/home/airflow/.local/lib/python3.8/site-packages/airflow/operators/bash.py", line 210, in execute
    raise AirflowException(
airflow.exceptions.AirflowException: Bash command failed. The command returned a non-zero exit code 2.
[2025-01-23T12:29:39.653+0000] {taskinstance.py:1400} INFO - Marking task as UP_FOR_RETRY. dag_id=hello_***, task_id=etl_task, execution_date=20250123T121419, start_date=20250123T122939, end_date=20250123T122939
[2025-01-23T12:29:39.663+0000] {standard_task_runner.py:104} ERROR - Failed to execute job 11 for task etl_task (Bash command failed. The command returned a non-zero exit code 2.; 602)
[2025-01-23T12:29:39.672+0000] {local_task_job_runner.py:228} INFO - Task exited with return code 1
[2025-01-23T12:29:39.684+0000] {taskinstance.py:2784} INFO - 0 downstream tasks scheduled from follow-on schedule check
