[2025-01-30T07:38:37.919+0000] {local_task_job_runner.py:123} INFO - ::group::Pre task execution logs
[2025-01-30T07:38:37.963+0000] {taskinstance.py:2613} INFO - Dependencies all met for dep_context=non-requeueable deps ti=<TaskInstance: hello_airflow.etl_task manual__2025-01-23T12:14:19.972456+00:00 [queued]>
[2025-01-30T07:38:37.982+0000] {taskinstance.py:2613} INFO - Dependencies all met for dep_context=requeueable deps ti=<TaskInstance: hello_airflow.etl_task manual__2025-01-23T12:14:19.972456+00:00 [queued]>
[2025-01-30T07:38:37.983+0000] {taskinstance.py:2866} INFO - Starting attempt 21 of 22
[2025-01-30T07:38:38.005+0000] {taskinstance.py:2889} INFO - Executing <Task(BashOperator): etl_task> on 2025-01-23 12:14:19.972456+00:00
[2025-01-30T07:38:38.015+0000] {standard_task_runner.py:104} INFO - Running: ['***', 'tasks', 'run', 'hello_***', 'etl_task', 'manual__2025-01-23T12:14:19.972456+00:00', '--job-id', '90', '--raw', '--subdir', 'DAGS_FOLDER/pipeline.py', '--cfg-path', '/tmp/tmphpketnhp']
[2025-01-30T07:38:38.021+0000] {standard_task_runner.py:105} INFO - Job 90: Subtask etl_task
[2025-01-30T07:38:38.023+0000] {logging_mixin.py:190} WARNING - /home/***/.local/lib/python3.12/site-packages/***/task/task_runner/standard_task_runner.py:70 DeprecationWarning: This process (pid=240) is multi-threaded, use of fork() may lead to deadlocks in the child.
[2025-01-30T07:38:38.024+0000] {standard_task_runner.py:72} INFO - Started process 241 to run task
[2025-01-30T07:38:38.128+0000] {task_command.py:467} INFO - Running <TaskInstance: hello_airflow.etl_task manual__2025-01-23T12:14:19.972456+00:00 [running]> on host 02e51acdb36a
[2025-01-30T07:38:38.259+0000] {taskinstance.py:3132} INFO - Exporting env vars: AIRFLOW_CTX_DAG_OWNER='***' AIRFLOW_CTX_DAG_ID='hello_***' AIRFLOW_CTX_TASK_ID='etl_task' AIRFLOW_CTX_EXECUTION_DATE='2025-01-23T12:14:19.972456+00:00' AIRFLOW_CTX_TRY_NUMBER='21' AIRFLOW_CTX_DAG_RUN_ID='manual__2025-01-23T12:14:19.972456+00:00'
[2025-01-30T07:38:38.260+0000] {taskinstance.py:731} INFO - ::endgroup::
[2025-01-30T07:38:38.299+0000] {subprocess.py:78} INFO - Tmp dir root location: /tmp
[2025-01-30T07:38:38.300+0000] {subprocess.py:88} INFO - Running command: ['/usr/bin/bash', '-c', 'python /opt/***/dags/etl.py']
[2025-01-30T07:38:38.310+0000] {subprocess.py:99} INFO - Output:
[2025-01-30T07:38:39.766+0000] {subprocess.py:106} INFO - /home/***/.local/lib/python3.12/site-packages/pyspark/bin/load-spark-env.sh: line 68: ps: command not found
[2025-01-30T07:38:39.767+0000] {subprocess.py:106} INFO - JAVA_HOME is not set
[2025-01-30T07:38:39.828+0000] {subprocess.py:106} INFO - Traceback (most recent call last):
[2025-01-30T07:38:39.829+0000] {subprocess.py:106} INFO -   File "/opt/***/dags/etl.py", line 8, in <module>
[2025-01-30T07:38:39.830+0000] {subprocess.py:106} INFO -     spark = SparkSession.builder.appName("spark").getOrCreate()
[2025-01-30T07:38:39.831+0000] {subprocess.py:106} INFO -             ^^^^^^^^^^^^^^^^^^^^^^^^^^^^^^^^^^^^^^^^^^^^^^^^^^^
[2025-01-30T07:38:39.831+0000] {subprocess.py:106} INFO -   File "/home/***/.local/lib/python3.12/site-packages/pyspark/sql/session.py", line 497, in getOrCreate
[2025-01-30T07:38:39.832+0000] {subprocess.py:106} INFO -     sc = SparkContext.getOrCreate(sparkConf)
[2025-01-30T07:38:39.832+0000] {subprocess.py:106} INFO -          ^^^^^^^^^^^^^^^^^^^^^^^^^^^^^^^^^^^
[2025-01-30T07:38:39.832+0000] {subprocess.py:106} INFO -   File "/home/***/.local/lib/python3.12/site-packages/pyspark/context.py", line 515, in getOrCreate
[2025-01-30T07:38:39.833+0000] {subprocess.py:106} INFO -     SparkContext(conf=conf or SparkConf())
[2025-01-30T07:38:39.833+0000] {subprocess.py:106} INFO -   File "/home/***/.local/lib/python3.12/site-packages/pyspark/context.py", line 201, in __init__
[2025-01-30T07:38:39.834+0000] {subprocess.py:106} INFO -     SparkContext._ensure_initialized(self, gateway=gateway, conf=conf)
[2025-01-30T07:38:39.834+0000] {subprocess.py:106} INFO -   File "/home/***/.local/lib/python3.12/site-packages/pyspark/context.py", line 436, in _ensure_initialized
[2025-01-30T07:38:39.835+0000] {subprocess.py:106} INFO -     SparkContext._gateway = gateway or launch_gateway(conf)
[2025-01-30T07:38:39.836+0000] {subprocess.py:106} INFO -                                        ^^^^^^^^^^^^^^^^^^^^
[2025-01-30T07:38:39.836+0000] {subprocess.py:106} INFO -   File "/home/***/.local/lib/python3.12/site-packages/pyspark/java_gateway.py", line 107, in launch_gateway
[2025-01-30T07:38:39.836+0000] {subprocess.py:106} INFO -     raise PySparkRuntimeError(
[2025-01-30T07:38:39.837+0000] {subprocess.py:106} INFO - pyspark.errors.exceptions.base.PySparkRuntimeError: [JAVA_GATEWAY_EXITED] Java gateway process exited before sending its port number.
[2025-01-30T07:38:40.021+0000] {subprocess.py:110} INFO - Command exited with return code 1
[2025-01-30T07:38:40.038+0000] {taskinstance.py:3311} ERROR - Task failed with exception
Traceback (most recent call last):
  File "/home/airflow/.local/lib/python3.12/site-packages/airflow/models/taskinstance.py", line 767, in _execute_task
    result = _execute_callable(context=context, **execute_callable_kwargs)
             ^^^^^^^^^^^^^^^^^^^^^^^^^^^^^^^^^^^^^^^^^^^^^^^^^^^^^^^^^^^^^
  File "/home/airflow/.local/lib/python3.12/site-packages/airflow/models/taskinstance.py", line 733, in _execute_callable
    return ExecutionCallableRunner(
           ^^^^^^^^^^^^^^^^^^^^^^^^
  File "/home/airflow/.local/lib/python3.12/site-packages/airflow/utils/operator_helpers.py", line 252, in run
    return self.func(*args, **kwargs)
           ^^^^^^^^^^^^^^^^^^^^^^^^^^
  File "/home/airflow/.local/lib/python3.12/site-packages/airflow/models/baseoperator.py", line 422, in wrapper
    return func(self, *args, **kwargs)
           ^^^^^^^^^^^^^^^^^^^^^^^^^^^
  File "/home/airflow/.local/lib/python3.12/site-packages/airflow/operators/bash.py", line 276, in execute
    raise AirflowException(
airflow.exceptions.AirflowException: Bash command failed. The command returned a non-zero exit code 1.
[2025-01-30T07:38:40.050+0000] {taskinstance.py:1225} INFO - Marking task as UP_FOR_RETRY. dag_id=hello_***, task_id=etl_task, run_id=manual__2025-01-23T12:14:19.972456+00:00, execution_date=20250123T121419, start_date=20250130T073837, end_date=20250130T073840
[2025-01-30T07:38:40.097+0000] {taskinstance.py:340} INFO - ::group::Post task execution logs
[2025-01-30T07:38:40.098+0000] {standard_task_runner.py:124} ERROR - Failed to execute job 90 for task etl_task (Bash command failed. The command returned a non-zero exit code 1.; 241)
Traceback (most recent call last):
  File "/home/airflow/.local/lib/python3.12/site-packages/airflow/task/task_runner/standard_task_runner.py", line 117, in _start_by_fork
    ret = args.func(args, dag=self.dag)
          ^^^^^^^^^^^^^^^^^^^^^^^^^^^^^
  File "/home/airflow/.local/lib/python3.12/site-packages/airflow/cli/cli_config.py", line 49, in command
    return func(*args, **kwargs)
           ^^^^^^^^^^^^^^^^^^^^^
  File "/home/airflow/.local/lib/python3.12/site-packages/airflow/utils/cli.py", line 116, in wrapper
    return f(*args, **kwargs)
           ^^^^^^^^^^^^^^^^^^
  File "/home/airflow/.local/lib/python3.12/site-packages/airflow/cli/commands/task_command.py", line 483, in task_run
    task_return_code = _run_task_by_selected_method(args, _dag, ti)
                       ^^^^^^^^^^^^^^^^^^^^^^^^^^^^^^^^^^^^^^^^^^^^
  File "/home/airflow/.local/lib/python3.12/site-packages/airflow/cli/commands/task_command.py", line 256, in _run_task_by_selected_method
    return _run_raw_task(args, ti)
           ^^^^^^^^^^^^^^^^^^^^^^^
  File "/home/airflow/.local/lib/python3.12/site-packages/airflow/cli/commands/task_command.py", line 341, in _run_raw_task
    return ti._run_raw_task(
           ^^^^^^^^^^^^^^^^^
  File "/home/airflow/.local/lib/python3.12/site-packages/airflow/utils/session.py", line 97, in wrapper
    return func(*args, session=session, **kwargs)
           ^^^^^^^^^^^^^^^^^^^^^^^^^^^^^^^^^^^^^^
  File "/home/airflow/.local/lib/python3.12/site-packages/airflow/models/taskinstance.py", line 3005, in _run_raw_task
    return _run_raw_task(
           ^^^^^^^^^^^^^^
  File "/home/airflow/.local/lib/python3.12/site-packages/airflow/models/taskinstance.py", line 273, in _run_raw_task
    TaskInstance._execute_task_with_callbacks(
  File "/home/airflow/.local/lib/python3.12/site-packages/airflow/models/taskinstance.py", line 3159, in _execute_task_with_callbacks
    result = self._execute_task(context, task_orig)
             ^^^^^^^^^^^^^^^^^^^^^^^^^^^^^^^^^^^^^^
  File "/home/airflow/.local/lib/python3.12/site-packages/airflow/models/taskinstance.py", line 3183, in _execute_task
    return _execute_task(self, context, task_orig)
           ^^^^^^^^^^^^^^^^^^^^^^^^^^^^^^^^^^^^^^^
  File "/home/airflow/.local/lib/python3.12/site-packages/airflow/models/taskinstance.py", line 767, in _execute_task
    result = _execute_callable(context=context, **execute_callable_kwargs)
             ^^^^^^^^^^^^^^^^^^^^^^^^^^^^^^^^^^^^^^^^^^^^^^^^^^^^^^^^^^^^^
  File "/home/airflow/.local/lib/python3.12/site-packages/airflow/models/taskinstance.py", line 733, in _execute_callable
    return ExecutionCallableRunner(
           ^^^^^^^^^^^^^^^^^^^^^^^^
  File "/home/airflow/.local/lib/python3.12/site-packages/airflow/utils/operator_helpers.py", line 252, in run
    return self.func(*args, **kwargs)
           ^^^^^^^^^^^^^^^^^^^^^^^^^^
  File "/home/airflow/.local/lib/python3.12/site-packages/airflow/models/baseoperator.py", line 422, in wrapper
    return func(self, *args, **kwargs)
           ^^^^^^^^^^^^^^^^^^^^^^^^^^^
  File "/home/airflow/.local/lib/python3.12/site-packages/airflow/operators/bash.py", line 276, in execute
    raise AirflowException(
airflow.exceptions.AirflowException: Bash command failed. The command returned a non-zero exit code 1.
[2025-01-30T07:38:40.148+0000] {local_task_job_runner.py:266} INFO - Task exited with return code 1
[2025-01-30T07:38:40.182+0000] {taskinstance.py:3895} INFO - 0 downstream tasks scheduled from follow-on schedule check
[2025-01-30T07:38:40.187+0000] {local_task_job_runner.py:245} INFO - ::endgroup::
