[2025-01-30T09:04:14.150+0000] {local_task_job_runner.py:123} INFO - ::group::Pre task execution logs
[2025-01-30T09:04:14.167+0000] {taskinstance.py:2613} INFO - Dependencies all met for dep_context=non-requeueable deps ti=<TaskInstance: hello_airflow.ml_task manual__2025-01-23T12:14:19.972456+00:00 [queued]>
[2025-01-30T09:04:14.172+0000] {taskinstance.py:2613} INFO - Dependencies all met for dep_context=requeueable deps ti=<TaskInstance: hello_airflow.ml_task manual__2025-01-23T12:14:19.972456+00:00 [queued]>
[2025-01-30T09:04:14.173+0000] {taskinstance.py:2866} INFO - Starting attempt 1 of 2
[2025-01-30T09:04:14.183+0000] {taskinstance.py:2889} INFO - Executing <Task(BashOperator): ml_task> on 2025-01-23 12:14:19.972456+00:00
[2025-01-30T09:04:14.189+0000] {logging_mixin.py:190} WARNING - /home/***/.local/lib/python3.12/site-packages/***/task/task_runner/standard_task_runner.py:70 DeprecationWarning: This process (pid=972) is multi-threaded, use of fork() may lead to deadlocks in the child.
[2025-01-30T09:04:14.188+0000] {standard_task_runner.py:104} INFO - Running: ['***', 'tasks', 'run', 'hello_***', 'ml_task', 'manual__2025-01-23T12:14:19.972456+00:00', '--job-id', '107', '--raw', '--subdir', 'DAGS_FOLDER/pipeline.py', '--cfg-path', '/tmp/tmpgatmlfvl']
[2025-01-30T09:04:14.190+0000] {standard_task_runner.py:105} INFO - Job 107: Subtask ml_task
[2025-01-30T09:04:14.190+0000] {standard_task_runner.py:72} INFO - Started process 973 to run task
[2025-01-30T09:04:14.225+0000] {task_command.py:467} INFO - Running <TaskInstance: hello_airflow.ml_task manual__2025-01-23T12:14:19.972456+00:00 [running]> on host 878723ee9d16
[2025-01-30T09:04:14.288+0000] {taskinstance.py:3132} INFO - Exporting env vars: AIRFLOW_CTX_DAG_OWNER='***' AIRFLOW_CTX_DAG_ID='hello_***' AIRFLOW_CTX_TASK_ID='ml_task' AIRFLOW_CTX_EXECUTION_DATE='2025-01-23T12:14:19.972456+00:00' AIRFLOW_CTX_TRY_NUMBER='1' AIRFLOW_CTX_DAG_RUN_ID='manual__2025-01-23T12:14:19.972456+00:00'
[2025-01-30T09:04:14.289+0000] {taskinstance.py:731} INFO - ::endgroup::
[2025-01-30T09:04:14.300+0000] {subprocess.py:78} INFO - Tmp dir root location: /tmp
[2025-01-30T09:04:14.301+0000] {subprocess.py:88} INFO - Running command: ['/usr/bin/bash', '-c', 'python /opt/***/dags/ml.py']
[2025-01-30T09:04:14.307+0000] {subprocess.py:99} INFO - Output:
[2025-01-30T09:04:15.816+0000] {subprocess.py:106} INFO - Traceback (most recent call last):
[2025-01-30T09:04:15.817+0000] {subprocess.py:106} INFO -   File "/opt/***/dags/ml.py", line 15, in <module>
[2025-01-30T09:04:15.817+0000] {subprocess.py:106} INFO -     df = pd.read_csv('opt/***/data/modified/spotify_etl_data.csv')
[2025-01-30T09:04:15.817+0000] {subprocess.py:106} INFO -          ^^^^^^^^^^^^^^^^^^^^^^^^^^^^^^^^^^^^^^^^^^^^^^^^^^^^^^^^^^^^^
[2025-01-30T09:04:15.817+0000] {subprocess.py:106} INFO -   File "/home/***/.local/lib/python3.12/site-packages/pandas/io/parsers/readers.py", line 1026, in read_csv
[2025-01-30T09:04:15.817+0000] {subprocess.py:106} INFO -     return _read(filepath_or_buffer, kwds)
[2025-01-30T09:04:15.817+0000] {subprocess.py:106} INFO -            ^^^^^^^^^^^^^^^^^^^^^^^^^^^^^^^
[2025-01-30T09:04:15.817+0000] {subprocess.py:106} INFO -   File "/home/***/.local/lib/python3.12/site-packages/pandas/io/parsers/readers.py", line 620, in _read
[2025-01-30T09:04:15.817+0000] {subprocess.py:106} INFO -     parser = TextFileReader(filepath_or_buffer, **kwds)
[2025-01-30T09:04:15.817+0000] {subprocess.py:106} INFO -              ^^^^^^^^^^^^^^^^^^^^^^^^^^^^^^^^^^^^^^^^^^
[2025-01-30T09:04:15.817+0000] {subprocess.py:106} INFO -   File "/home/***/.local/lib/python3.12/site-packages/pandas/io/parsers/readers.py", line 1620, in __init__
[2025-01-30T09:04:15.817+0000] {subprocess.py:106} INFO -     self._engine = self._make_engine(f, self.engine)
[2025-01-30T09:04:15.817+0000] {subprocess.py:106} INFO -                    ^^^^^^^^^^^^^^^^^^^^^^^^^^^^^^^^^
[2025-01-30T09:04:15.818+0000] {subprocess.py:106} INFO -   File "/home/***/.local/lib/python3.12/site-packages/pandas/io/parsers/readers.py", line 1880, in _make_engine
[2025-01-30T09:04:15.818+0000] {subprocess.py:106} INFO -     self.handles = get_handle(
[2025-01-30T09:04:15.818+0000] {subprocess.py:106} INFO -                    ^^^^^^^^^^^
[2025-01-30T09:04:15.818+0000] {subprocess.py:106} INFO -   File "/home/***/.local/lib/python3.12/site-packages/pandas/io/common.py", line 873, in get_handle
[2025-01-30T09:04:15.818+0000] {subprocess.py:106} INFO -     handle = open(
[2025-01-30T09:04:15.818+0000] {subprocess.py:106} INFO -              ^^^^^
[2025-01-30T09:04:15.818+0000] {subprocess.py:106} INFO - FileNotFoundError: [Errno 2] No such file or directory: 'opt/***/data/modified/spotify_etl_data.csv'
[2025-01-30T09:04:15.969+0000] {subprocess.py:110} INFO - Command exited with return code 1
[2025-01-30T09:04:15.978+0000] {taskinstance.py:3311} ERROR - Task failed with exception
Traceback (most recent call last):
  File "/home/airflow/.local/lib/python3.12/site-packages/airflow/models/taskinstance.py", line 767, in _execute_task
    result = _execute_callable(context=context, **execute_callable_kwargs)
             ^^^^^^^^^^^^^^^^^^^^^^^^^^^^^^^^^^^^^^^^^^^^^^^^^^^^^^^^^^^^^
  File "/home/airflow/.local/lib/python3.12/site-packages/airflow/models/taskinstance.py", line 733, in _execute_callable
    return ExecutionCallableRunner(
           ^^^^^^^^^^^^^^^^^^^^^^^^
  File "/home/airflow/.local/lib/python3.12/site-packages/airflow/utils/operator_helpers.py", line 252, in run
    return self.func(*args, **kwargs)
           ^^^^^^^^^^^^^^^^^^^^^^^^^^
  File "/home/airflow/.local/lib/python3.12/site-packages/airflow/models/baseoperator.py", line 422, in wrapper
    return func(self, *args, **kwargs)
           ^^^^^^^^^^^^^^^^^^^^^^^^^^^
  File "/home/airflow/.local/lib/python3.12/site-packages/airflow/operators/bash.py", line 276, in execute
    raise AirflowException(
airflow.exceptions.AirflowException: Bash command failed. The command returned a non-zero exit code 1.
[2025-01-30T09:04:15.985+0000] {taskinstance.py:1225} INFO - Marking task as UP_FOR_RETRY. dag_id=hello_***, task_id=ml_task, run_id=manual__2025-01-23T12:14:19.972456+00:00, execution_date=20250123T121419, start_date=20250130T090414, end_date=20250130T090415
[2025-01-30T09:04:16.009+0000] {taskinstance.py:340} INFO - ::group::Post task execution logs
[2025-01-30T09:04:16.010+0000] {standard_task_runner.py:124} ERROR - Failed to execute job 107 for task ml_task (Bash command failed. The command returned a non-zero exit code 1.; 973)
Traceback (most recent call last):
  File "/home/airflow/.local/lib/python3.12/site-packages/airflow/task/task_runner/standard_task_runner.py", line 117, in _start_by_fork
    ret = args.func(args, dag=self.dag)
          ^^^^^^^^^^^^^^^^^^^^^^^^^^^^^
  File "/home/airflow/.local/lib/python3.12/site-packages/airflow/cli/cli_config.py", line 49, in command
    return func(*args, **kwargs)
           ^^^^^^^^^^^^^^^^^^^^^
  File "/home/airflow/.local/lib/python3.12/site-packages/airflow/utils/cli.py", line 116, in wrapper
    return f(*args, **kwargs)
           ^^^^^^^^^^^^^^^^^^
  File "/home/airflow/.local/lib/python3.12/site-packages/airflow/cli/commands/task_command.py", line 483, in task_run
    task_return_code = _run_task_by_selected_method(args, _dag, ti)
                       ^^^^^^^^^^^^^^^^^^^^^^^^^^^^^^^^^^^^^^^^^^^^
  File "/home/airflow/.local/lib/python3.12/site-packages/airflow/cli/commands/task_command.py", line 256, in _run_task_by_selected_method
    return _run_raw_task(args, ti)
           ^^^^^^^^^^^^^^^^^^^^^^^
  File "/home/airflow/.local/lib/python3.12/site-packages/airflow/cli/commands/task_command.py", line 341, in _run_raw_task
    return ti._run_raw_task(
           ^^^^^^^^^^^^^^^^^
  File "/home/airflow/.local/lib/python3.12/site-packages/airflow/utils/session.py", line 97, in wrapper
    return func(*args, session=session, **kwargs)
           ^^^^^^^^^^^^^^^^^^^^^^^^^^^^^^^^^^^^^^
  File "/home/airflow/.local/lib/python3.12/site-packages/airflow/models/taskinstance.py", line 3005, in _run_raw_task
    return _run_raw_task(
           ^^^^^^^^^^^^^^
  File "/home/airflow/.local/lib/python3.12/site-packages/airflow/models/taskinstance.py", line 273, in _run_raw_task
    TaskInstance._execute_task_with_callbacks(
  File "/home/airflow/.local/lib/python3.12/site-packages/airflow/models/taskinstance.py", line 3159, in _execute_task_with_callbacks
    result = self._execute_task(context, task_orig)
             ^^^^^^^^^^^^^^^^^^^^^^^^^^^^^^^^^^^^^^
  File "/home/airflow/.local/lib/python3.12/site-packages/airflow/models/taskinstance.py", line 3183, in _execute_task
    return _execute_task(self, context, task_orig)
           ^^^^^^^^^^^^^^^^^^^^^^^^^^^^^^^^^^^^^^^
  File "/home/airflow/.local/lib/python3.12/site-packages/airflow/models/taskinstance.py", line 767, in _execute_task
    result = _execute_callable(context=context, **execute_callable_kwargs)
             ^^^^^^^^^^^^^^^^^^^^^^^^^^^^^^^^^^^^^^^^^^^^^^^^^^^^^^^^^^^^^
  File "/home/airflow/.local/lib/python3.12/site-packages/airflow/models/taskinstance.py", line 733, in _execute_callable
    return ExecutionCallableRunner(
           ^^^^^^^^^^^^^^^^^^^^^^^^
  File "/home/airflow/.local/lib/python3.12/site-packages/airflow/utils/operator_helpers.py", line 252, in run
    return self.func(*args, **kwargs)
           ^^^^^^^^^^^^^^^^^^^^^^^^^^
  File "/home/airflow/.local/lib/python3.12/site-packages/airflow/models/baseoperator.py", line 422, in wrapper
    return func(self, *args, **kwargs)
           ^^^^^^^^^^^^^^^^^^^^^^^^^^^
  File "/home/airflow/.local/lib/python3.12/site-packages/airflow/operators/bash.py", line 276, in execute
    raise AirflowException(
airflow.exceptions.AirflowException: Bash command failed. The command returned a non-zero exit code 1.
[2025-01-30T09:04:16.055+0000] {local_task_job_runner.py:266} INFO - Task exited with return code 1
[2025-01-30T09:04:16.073+0000] {taskinstance.py:3895} INFO - 0 downstream tasks scheduled from follow-on schedule check
[2025-01-30T09:04:16.074+0000] {local_task_job_runner.py:245} INFO - ::endgroup::
